<?xml version="1.0" ?>
<robot name="mbot" xmlns:xacro="http://ros.org/wiki/xacro">
    <xacro:property name="pi" value="3.14159265359"/>
    <material name="black">
        <color rgba="0.0 0.0 0.0 1.0"/>
    </material>

    <material name="dark">
    <color rgba="0.3 0.3 0.3 1.0"/>
    </material>

    <material name="light_black">
    <color rgba="0.4 0.4 0.4 1.0"/>
    </material>

    <material name="blue">
    <color rgba="0.0 0.0 0.8 1.0"/>
    </material>

    <material name="green">
    <color rgba="0.0 0.8 0.0 1.0"/>
    </material>

    <material name="grey">
    <color rgba="0.5 0.5 0.5 1.0"/>
    </material>

    <material name="orange">
    <color rgba="1.0 0.4235 0.0392 1.0"/>
    </material>

    <material name="brown">
    <color rgba="0.8706 0.8118 0.7647 1.0"/>
    </material>

    <material name="red">
    <color rgba="0.8 0.0 0.0 1.0"/>
    </material>

    <material name="white">
    <color rgba="1.0 1.0 1.0 1.0"/>
    </material>


    <link name="base_link">
        <visual>
            <origin xyz=" 0 0 0.18" rpy="0 0 0" />
            <geometry>
                <cylinder length="0.3" radius="0.165"/>
            </geometry>
            <material name="yellow">
                <color rgba="1 0.4 0 1"/>
            </material>
        </visual>
        <collision>
            <origin xyz=" 0 0 0.18" rpy="0 0 0" />
            <geometry>
                <cylinder length="0.3" radius="0.165"/>
            </geometry>
        </collision>
    </link>

    <joint name="left_wheel_joint" type="continuous">
        <origin xyz="0 0.165 0.068" rpy="0 0 0"/>
        <parent link="base_link"/>
        <child link="left_wheel_link"/>
        <axis xyz="0 1 0"/>
    </joint>

    <link name="left_wheel_link">
        <visual>
            <origin xyz="0 0 0" rpy="${pi/2} 0 0" />
            <geometry>
                <cylinder radius="0.068" length = "0.024"/>
            </geometry>
            <material name="white">
                <color rgba="1 1 1 0.9"/>
            </material>
        </visual>
        <!-- <collision>
            <origin xyz="0 0 0" rpy="${pi/2} 0 0" />
            <geometry>
                <cylinder radius="0.068" length = "0.024"/>
            </geometry>
        </collision> -->
    </link>

    <joint name="right_wheel_joint" type="continuous">
        <origin xyz="0 -0.165 0.068" rpy="0 0 0"/>
        <parent link="base_link"/>
        <child link="right_wheel_link"/>
        <axis xyz="0 1 0"/>
    </joint>

    <link name="right_wheel_link">
        <visual>
            <origin xyz="0 0 0" rpy="${pi/2} 0 0" />
            <geometry>
                <cylinder radius="0.068" length = "0.024"/>
            </geometry>
            <material name="white">
                <color rgba="1 1 1 0.9"/>
            </material>
        </visual>
        <!-- <collision>
            <origin xyz="0 0 0" rpy="${pi/2} 0 0" />
            <geometry>
                <cylinder radius="0.068" length = "0.024"/>
            </geometry>
        </collision> -->
    </link>

    <joint name="front_caster_joint" type="continuous">
        <origin xyz="0.13 0 0.03" rpy="0 0 0"/>
        <parent link="base_link"/>
        <child link="front_caster_link"/>
        <axis xyz="0 1 0"/>
    </joint>

    <link name="front_caster_link">
        <visual>
            <origin xyz="0 0 0" rpy="0 0 0"/>
            <geometry>
                <sphere radius="0.03" />
            </geometry>
            <material name="black">
                <color rgba="0 0 0 0.95"/>
            </material>
        </visual>
    </link>

    <joint name="back_caster_joint" type="continuous">
        <origin xyz="-0.13 0 0.03" rpy="0 0 0"/>
        <parent link="base_link"/>
        <child link="back_caster_link"/>
        <axis xyz="0 1 0"/>
    </joint>

    <link name="back_caster_link">
        <visual>
            <origin xyz="0 0 0" rpy="0 0 0"/>
            <geometry>
                <sphere radius="0.03" />
            </geometry>
            <material name="black">
                <color rgba="0 0 0 0.95"/>
            </material>
        </visual>
    </link>

    <link name="camera_link">
        <visual>
            <origin xyz=" 0 0 0 " rpy="0 0 0" />
            <geometry>
                <box size="0.03 0.04 0.04" />
            </geometry>
            <material name="black">
                <color rgba="0 0 0 0.95"/>
            </material>
        </visual>
    </link>

    <joint name="camera_joint" type="fixed">
        <origin xyz="0.16 0 0.25" rpy="0 0 0"/>
        <parent link="base_link"/>
        <child link="camera_link"/>
    </joint>

    <joint name="scan_joint" type="fixed">
    <parent link="base_link"/>
    <child link="scan_link"/>
    <origin xyz="0 0 0.36" rpy="0 0 0"/>
    </joint>

    <link name="scan_link">
    <visual>
        <origin xyz="0 0 0" rpy="0 0 0"/>
        <geometry>
        <mesh filename="package://hcr_robot/meshes/lds.dae" scale="0.001 0.001 0.001"/>
        </geometry>
        <material name="dark"/>
    </visual>

    <collision>
        <origin xyz="0.015 0 -0.0065" rpy="0 0 0"/>
        <geometry>
        <cylinder length="0.0315" radius="0.055"/>
        </geometry>
    </collision>

    <inertial>
        <mass value="0.114" />
        <origin xyz="0 0 0" />
        <inertia ixx="0.001" ixy="0.0" ixz="0.0"
                iyy="0.001" iyz="0.0"
                izz="0.001" />
    </inertial>
    </link>

</robot>
